ERROR 2025-10-24 15:22:05,472 log 25460 22536 Internal Server Error: /admin/
Traceback (most recent call last):
  File "C:\Users\PC\Desktop\intenship\protfolio\venv\Lib\site-packages\django\contrib\sessions\backends\base.py", line 244, in _get_session
    return self._session_cache
           ^^^^^^^^^^^^^^^^^^^
AttributeError: 'SessionStore' object has no attribute '_session_cache'

During handling of the above exception, another exception occurred:

Traceback (most recent call last):
  File "C:\Users\PC\Desktop\intenship\protfolio\venv\Lib\site-packages\django\db\backends\utils.py", line 103, in _execute
    return self.cursor.execute(sql)
           ~~~~~~~~~~~~~~~~~~~^^^^^
  File "C:\Users\PC\Desktop\intenship\protfolio\venv\Lib\site-packages\django\db\backends\sqlite3\base.py", line 356, in execute
    return super().execute(query)
           ~~~~~~~~~~~~~~~^^^^^^^
sqlite3.OperationalError: no such table: myapp_cache_table

The above exception was the direct cause of the following exception:

Traceback (most recent call last):
  File "C:\Users\PC\Desktop\intenship\protfolio\venv\Lib\site-packages\django\core\handlers\exception.py", line 55, in inner
    response = get_response(request)
  File "C:\Users\PC\Desktop\intenship\protfolio\myproject\myapp\middleware.py", line 147, in __call__
    logger.info(f"Request: {request.method} {request.path} - IP: {self.get_client_ip(request)} - User: {request.user}")
                                                                                                       ^^^^^^^^^^^^^^
  File "C:\Users\PC\Desktop\intenship\protfolio\venv\Lib\site-packages\django\utils\functional.py", line 251, in inner
    self._setup()
    ~~~~~~~~~~~^^
  File "C:\Users\PC\Desktop\intenship\protfolio\venv\Lib\site-packages\django\utils\functional.py", line 404, in _setup
    self._wrapped = self._setupfunc()
                    ~~~~~~~~~~~~~~~^^
  File "C:\Users\PC\Desktop\intenship\protfolio\venv\Lib\site-packages\django\contrib\auth\middleware.py", line 40, in <lambda>
    request.user = SimpleLazyObject(lambda: get_user(request))
                                            ~~~~~~~~^^^^^^^^^
  File "C:\Users\PC\Desktop\intenship\protfolio\venv\Lib\site-packages\django\contrib\auth\middleware.py", line 20, in get_user
    request._cached_user = auth.get_user(request)
                           ~~~~~~~~~~~~~^^^^^^^^^
  File "C:\Users\PC\Desktop\intenship\protfolio\venv\Lib\site-packages\django\contrib\auth\__init__.py", line 304, in get_user
    user_id = _get_user_session_key(request)
  File "C:\Users\PC\Desktop\intenship\protfolio\venv\Lib\site-packages\django\contrib\auth\__init__.py", line 95, in _get_user_session_key
    return get_user_model()._meta.pk.to_python(request.session[SESSION_KEY])
                                               ~~~~~~~~~~~~~~~^^^^^^^^^^^^^
  File "C:\Users\PC\Desktop\intenship\protfolio\venv\Lib\site-packages\django\contrib\sessions\backends\base.py", line 55, in __getitem__
    return self._session[key]
           ^^^^^^^^^^^^^
  File "C:\Users\PC\Desktop\intenship\protfolio\venv\Lib\site-packages\django\contrib\sessions\backends\base.py", line 249, in _get_session
    self._session_cache = self.load()
                          ~~~~~~~~~^^
  File "C:\Users\PC\Desktop\intenship\protfolio\venv\Lib\site-packages\django\contrib\sessions\backends\cached_db.py", line 46, in load
    self._cache.set(
    ~~~~~~~~~~~~~~~^
        self.cache_key, data, self.get_expiry_age(expiry=s.expire_date)
        ^^^^^^^^^^^^^^^^^^^^^^^^^^^^^^^^^^^^^^^^^^^^^^^^^^^^^^^^^^^^^^^
    )
    ^
  File "C:\Users\PC\Desktop\intenship\protfolio\venv\Lib\site-packages\django\core\cache\backends\db.py", line 103, in set
    self._base_set("set", key, value, timeout)
    ~~~~~~~~~~~~~~^^^^^^^^^^^^^^^^^^^^^^^^^^^^
  File "C:\Users\PC\Desktop\intenship\protfolio\venv\Lib\site-packages\django\core\cache\backends\db.py", line 121, in _base_set
    cursor.execute("SELECT COUNT(*) FROM %s" % table)
    ~~~~~~~~~~~~~~^^^^^^^^^^^^^^^^^^^^^^^^^^^^^^^^^^^
  File "C:\Users\PC\Desktop\intenship\protfolio\venv\Lib\site-packages\django\db\backends\utils.py", line 122, in execute
    return super().execute(sql, params)
           ~~~~~~~~~~~~~~~^^^^^^^^^^^^^
  File "C:\Users\PC\Desktop\intenship\protfolio\venv\Lib\site-packages\django\db\backends\utils.py", line 79, in execute
    return self._execute_with_wrappers(
           ~~~~~~~~~~~~~~~~~~~~~~~~~~~^
        sql, params, many=False, executor=self._execute
        ^^^^^^^^^^^^^^^^^^^^^^^^^^^^^^^^^^^^^^^^^^^^^^^
    )
    ^
  File "C:\Users\PC\Desktop\intenship\protfolio\venv\Lib\site-packages\django\db\backends\utils.py", line 92, in _execute_with_wrappers
    return executor(sql, params, many, context)
  File "C:\Users\PC\Desktop\intenship\protfolio\venv\Lib\site-packages\django\db\backends\utils.py", line 100, in _execute
    with self.db.wrap_database_errors:
         ^^^^^^^^^^^^^^^^^^^^^^^^^^^^
  File "C:\Users\PC\Desktop\intenship\protfolio\venv\Lib\site-packages\django\db\utils.py", line 91, in __exit__
    raise dj_exc_value.with_traceback(traceback) from exc_value
  File "C:\Users\PC\Desktop\intenship\protfolio\venv\Lib\site-packages\django\db\backends\utils.py", line 103, in _execute
    return self.cursor.execute(sql)
           ~~~~~~~~~~~~~~~~~~~^^^^^
  File "C:\Users\PC\Desktop\intenship\protfolio\venv\Lib\site-packages\django\db\backends\sqlite3\base.py", line 356, in execute
    return super().execute(query)
           ~~~~~~~~~~~~~~~^^^^^^^
django.db.utils.OperationalError: no such table: myapp_cache_table
ERROR 2025-10-24 15:22:05,572 basehttp 25460 22536 "GET /admin/ HTTP/1.1" 500 159387
ERROR 2025-10-24 15:22:15,949 log 25460 25972 Internal Server Error: /accounts/login/
Traceback (most recent call last):
  File "C:\Users\PC\Desktop\intenship\protfolio\venv\Lib\site-packages\django\contrib\sessions\backends\base.py", line 244, in _get_session
    return self._session_cache
           ^^^^^^^^^^^^^^^^^^^
AttributeError: 'SessionStore' object has no attribute '_session_cache'

During handling of the above exception, another exception occurred:

Traceback (most recent call last):
  File "C:\Users\PC\Desktop\intenship\protfolio\venv\Lib\site-packages\django\db\backends\utils.py", line 103, in _execute
    return self.cursor.execute(sql)
           ~~~~~~~~~~~~~~~~~~~^^^^^
  File "C:\Users\PC\Desktop\intenship\protfolio\venv\Lib\site-packages\django\db\backends\sqlite3\base.py", line 356, in execute
    return super().execute(query)
           ~~~~~~~~~~~~~~~^^^^^^^
sqlite3.OperationalError: no such table: myapp_cache_table

The above exception was the direct cause of the following exception:

Traceback (most recent call last):
  File "C:\Users\PC\Desktop\intenship\protfolio\venv\Lib\site-packages\django\core\handlers\exception.py", line 55, in inner
    response = get_response(request)
  File "C:\Users\PC\Desktop\intenship\protfolio\myproject\myapp\middleware.py", line 147, in __call__
    logger.info(f"Request: {request.method} {request.path} - IP: {self.get_client_ip(request)} - User: {request.user}")
                                                                                                       ^^^^^^^^^^^^^^
  File "C:\Users\PC\Desktop\intenship\protfolio\venv\Lib\site-packages\django\utils\functional.py", line 251, in inner
    self._setup()
    ~~~~~~~~~~~^^
  File "C:\Users\PC\Desktop\intenship\protfolio\venv\Lib\site-packages\django\utils\functional.py", line 404, in _setup
    self._wrapped = self._setupfunc()
                    ~~~~~~~~~~~~~~~^^
  File "C:\Users\PC\Desktop\intenship\protfolio\venv\Lib\site-packages\django\contrib\auth\middleware.py", line 40, in <lambda>
    request.user = SimpleLazyObject(lambda: get_user(request))
                                            ~~~~~~~~^^^^^^^^^
  File "C:\Users\PC\Desktop\intenship\protfolio\venv\Lib\site-packages\django\contrib\auth\middleware.py", line 20, in get_user
    request._cached_user = auth.get_user(request)
                           ~~~~~~~~~~~~~^^^^^^^^^
  File "C:\Users\PC\Desktop\intenship\protfolio\venv\Lib\site-packages\django\contrib\auth\__init__.py", line 304, in get_user
    user_id = _get_user_session_key(request)
  File "C:\Users\PC\Desktop\intenship\protfolio\venv\Lib\site-packages\django\contrib\auth\__init__.py", line 95, in _get_user_session_key
    return get_user_model()._meta.pk.to_python(request.session[SESSION_KEY])
                                               ~~~~~~~~~~~~~~~^^^^^^^^^^^^^
  File "C:\Users\PC\Desktop\intenship\protfolio\venv\Lib\site-packages\django\contrib\sessions\backends\base.py", line 55, in __getitem__
    return self._session[key]
           ^^^^^^^^^^^^^
  File "C:\Users\PC\Desktop\intenship\protfolio\venv\Lib\site-packages\django\contrib\sessions\backends\base.py", line 249, in _get_session
    self._session_cache = self.load()
                          ~~~~~~~~~^^
  File "C:\Users\PC\Desktop\intenship\protfolio\venv\Lib\site-packages\django\contrib\sessions\backends\cached_db.py", line 46, in load
    self._cache.set(
    ~~~~~~~~~~~~~~~^
        self.cache_key, data, self.get_expiry_age(expiry=s.expire_date)
        ^^^^^^^^^^^^^^^^^^^^^^^^^^^^^^^^^^^^^^^^^^^^^^^^^^^^^^^^^^^^^^^
    )
    ^
  File "C:\Users\PC\Desktop\intenship\protfolio\venv\Lib\site-packages\django\core\cache\backends\db.py", line 103, in set
    self._base_set("set", key, value, timeout)
    ~~~~~~~~~~~~~~^^^^^^^^^^^^^^^^^^^^^^^^^^^^
  File "C:\Users\PC\Desktop\intenship\protfolio\venv\Lib\site-packages\django\core\cache\backends\db.py", line 121, in _base_set
    cursor.execute("SELECT COUNT(*) FROM %s" % table)
    ~~~~~~~~~~~~~~^^^^^^^^^^^^^^^^^^^^^^^^^^^^^^^^^^^
  File "C:\Users\PC\Desktop\intenship\protfolio\venv\Lib\site-packages\django\db\backends\utils.py", line 122, in execute
    return super().execute(sql, params)
           ~~~~~~~~~~~~~~~^^^^^^^^^^^^^
  File "C:\Users\PC\Desktop\intenship\protfolio\venv\Lib\site-packages\django\db\backends\utils.py", line 79, in execute
    return self._execute_with_wrappers(
           ~~~~~~~~~~~~~~~~~~~~~~~~~~~^
        sql, params, many=False, executor=self._execute
        ^^^^^^^^^^^^^^^^^^^^^^^^^^^^^^^^^^^^^^^^^^^^^^^
    )
    ^
  File "C:\Users\PC\Desktop\intenship\protfolio\venv\Lib\site-packages\django\db\backends\utils.py", line 92, in _execute_with_wrappers
    return executor(sql, params, many, context)
  File "C:\Users\PC\Desktop\intenship\protfolio\venv\Lib\site-packages\django\db\backends\utils.py", line 100, in _execute
    with self.db.wrap_database_errors:
         ^^^^^^^^^^^^^^^^^^^^^^^^^^^^
  File "C:\Users\PC\Desktop\intenship\protfolio\venv\Lib\site-packages\django\db\utils.py", line 91, in __exit__
    raise dj_exc_value.with_traceback(traceback) from exc_value
  File "C:\Users\PC\Desktop\intenship\protfolio\venv\Lib\site-packages\django\db\backends\utils.py", line 103, in _execute
    return self.cursor.execute(sql)
           ~~~~~~~~~~~~~~~~~~~^^^^^
  File "C:\Users\PC\Desktop\intenship\protfolio\venv\Lib\site-packages\django\db\backends\sqlite3\base.py", line 356, in execute
    return super().execute(query)
           ~~~~~~~~~~~~~~~^^^^^^^
django.db.utils.OperationalError: no such table: myapp_cache_table
ERROR 2025-10-24 15:22:15,962 basehttp 25460 25972 "GET /accounts/login/ HTTP/1.1" 500 159240
ERROR 2025-10-24 15:22:38,285 log 25460 22896 Internal Server Error: /
Traceback (most recent call last):
  File "C:\Users\PC\Desktop\intenship\protfolio\venv\Lib\site-packages\django\contrib\sessions\backends\base.py", line 244, in _get_session
    return self._session_cache
           ^^^^^^^^^^^^^^^^^^^
AttributeError: 'SessionStore' object has no attribute '_session_cache'

During handling of the above exception, another exception occurred:

Traceback (most recent call last):
  File "C:\Users\PC\Desktop\intenship\protfolio\venv\Lib\site-packages\django\db\backends\utils.py", line 103, in _execute
    return self.cursor.execute(sql)
           ~~~~~~~~~~~~~~~~~~~^^^^^
  File "C:\Users\PC\Desktop\intenship\protfolio\venv\Lib\site-packages\django\db\backends\sqlite3\base.py", line 356, in execute
    return super().execute(query)
           ~~~~~~~~~~~~~~~^^^^^^^
sqlite3.OperationalError: no such table: myapp_cache_table

The above exception was the direct cause of the following exception:

Traceback (most recent call last):
  File "C:\Users\PC\Desktop\intenship\protfolio\venv\Lib\site-packages\django\core\handlers\exception.py", line 55, in inner
    response = get_response(request)
  File "C:\Users\PC\Desktop\intenship\protfolio\myproject\myapp\middleware.py", line 147, in __call__
    logger.info(f"Request: {request.method} {request.path} - IP: {self.get_client_ip(request)} - User: {request.user}")
                                                                                                       ^^^^^^^^^^^^^^
  File "C:\Users\PC\Desktop\intenship\protfolio\venv\Lib\site-packages\django\utils\functional.py", line 251, in inner
    self._setup()
    ~~~~~~~~~~~^^
  File "C:\Users\PC\Desktop\intenship\protfolio\venv\Lib\site-packages\django\utils\functional.py", line 404, in _setup
    self._wrapped = self._setupfunc()
                    ~~~~~~~~~~~~~~~^^
  File "C:\Users\PC\Desktop\intenship\protfolio\venv\Lib\site-packages\django\contrib\auth\middleware.py", line 40, in <lambda>
    request.user = SimpleLazyObject(lambda: get_user(request))
                                            ~~~~~~~~^^^^^^^^^
  File "C:\Users\PC\Desktop\intenship\protfolio\venv\Lib\site-packages\django\contrib\auth\middleware.py", line 20, in get_user
    request._cached_user = auth.get_user(request)
                           ~~~~~~~~~~~~~^^^^^^^^^
  File "C:\Users\PC\Desktop\intenship\protfolio\venv\Lib\site-packages\django\contrib\auth\__init__.py", line 304, in get_user
    user_id = _get_user_session_key(request)
  File "C:\Users\PC\Desktop\intenship\protfolio\venv\Lib\site-packages\django\contrib\auth\__init__.py", line 95, in _get_user_session_key
    return get_user_model()._meta.pk.to_python(request.session[SESSION_KEY])
                                               ~~~~~~~~~~~~~~~^^^^^^^^^^^^^
  File "C:\Users\PC\Desktop\intenship\protfolio\venv\Lib\site-packages\django\contrib\sessions\backends\base.py", line 55, in __getitem__
    return self._session[key]
           ^^^^^^^^^^^^^
  File "C:\Users\PC\Desktop\intenship\protfolio\venv\Lib\site-packages\django\contrib\sessions\backends\base.py", line 249, in _get_session
    self._session_cache = self.load()
                          ~~~~~~~~~^^
  File "C:\Users\PC\Desktop\intenship\protfolio\venv\Lib\site-packages\django\contrib\sessions\backends\cached_db.py", line 46, in load
    self._cache.set(
    ~~~~~~~~~~~~~~~^
        self.cache_key, data, self.get_expiry_age(expiry=s.expire_date)
        ^^^^^^^^^^^^^^^^^^^^^^^^^^^^^^^^^^^^^^^^^^^^^^^^^^^^^^^^^^^^^^^
    )
    ^
  File "C:\Users\PC\Desktop\intenship\protfolio\venv\Lib\site-packages\django\core\cache\backends\db.py", line 103, in set
    self._base_set("set", key, value, timeout)
    ~~~~~~~~~~~~~~^^^^^^^^^^^^^^^^^^^^^^^^^^^^
  File "C:\Users\PC\Desktop\intenship\protfolio\venv\Lib\site-packages\django\core\cache\backends\db.py", line 121, in _base_set
    cursor.execute("SELECT COUNT(*) FROM %s" % table)
    ~~~~~~~~~~~~~~^^^^^^^^^^^^^^^^^^^^^^^^^^^^^^^^^^^
  File "C:\Users\PC\Desktop\intenship\protfolio\venv\Lib\site-packages\django\db\backends\utils.py", line 122, in execute
    return super().execute(sql, params)
           ~~~~~~~~~~~~~~~^^^^^^^^^^^^^
  File "C:\Users\PC\Desktop\intenship\protfolio\venv\Lib\site-packages\django\db\backends\utils.py", line 79, in execute
    return self._execute_with_wrappers(
           ~~~~~~~~~~~~~~~~~~~~~~~~~~~^
        sql, params, many=False, executor=self._execute
        ^^^^^^^^^^^^^^^^^^^^^^^^^^^^^^^^^^^^^^^^^^^^^^^
    )
    ^
  File "C:\Users\PC\Desktop\intenship\protfolio\venv\Lib\site-packages\django\db\backends\utils.py", line 92, in _execute_with_wrappers
    return executor(sql, params, many, context)
  File "C:\Users\PC\Desktop\intenship\protfolio\venv\Lib\site-packages\django\db\backends\utils.py", line 100, in _execute
    with self.db.wrap_database_errors:
         ^^^^^^^^^^^^^^^^^^^^^^^^^^^^
  File "C:\Users\PC\Desktop\intenship\protfolio\venv\Lib\site-packages\django\db\utils.py", line 91, in __exit__
    raise dj_exc_value.with_traceback(traceback) from exc_value
  File "C:\Users\PC\Desktop\intenship\protfolio\venv\Lib\site-packages\django\db\backends\utils.py", line 103, in _execute
    return self.cursor.execute(sql)
           ~~~~~~~~~~~~~~~~~~~^^^^^
  File "C:\Users\PC\Desktop\intenship\protfolio\venv\Lib\site-packages\django\db\backends\sqlite3\base.py", line 356, in execute
    return super().execute(query)
           ~~~~~~~~~~~~~~~^^^^^^^
django.db.utils.OperationalError: no such table: myapp_cache_table
ERROR 2025-10-24 15:22:38,295 basehttp 25460 22896 "GET / HTTP/1.1" 500 159134
ERROR 2025-10-24 15:22:43,812 log 25460 22896 Internal Server Error: /
Traceback (most recent call last):
  File "C:\Users\PC\Desktop\intenship\protfolio\venv\Lib\site-packages\django\contrib\sessions\backends\base.py", line 244, in _get_session
    return self._session_cache
           ^^^^^^^^^^^^^^^^^^^
AttributeError: 'SessionStore' object has no attribute '_session_cache'

During handling of the above exception, another exception occurred:

Traceback (most recent call last):
  File "C:\Users\PC\Desktop\intenship\protfolio\venv\Lib\site-packages\django\db\backends\utils.py", line 103, in _execute
    return self.cursor.execute(sql)
           ~~~~~~~~~~~~~~~~~~~^^^^^
  File "C:\Users\PC\Desktop\intenship\protfolio\venv\Lib\site-packages\django\db\backends\sqlite3\base.py", line 356, in execute
    return super().execute(query)
           ~~~~~~~~~~~~~~~^^^^^^^
sqlite3.OperationalError: no such table: myapp_cache_table

The above exception was the direct cause of the following exception:

Traceback (most recent call last):
  File "C:\Users\PC\Desktop\intenship\protfolio\venv\Lib\site-packages\django\core\handlers\exception.py", line 55, in inner
    response = get_response(request)
  File "C:\Users\PC\Desktop\intenship\protfolio\myproject\myapp\middleware.py", line 147, in __call__
    logger.info(f"Request: {request.method} {request.path} - IP: {self.get_client_ip(request)} - User: {request.user}")
                                                                                                       ^^^^^^^^^^^^^^
  File "C:\Users\PC\Desktop\intenship\protfolio\venv\Lib\site-packages\django\utils\functional.py", line 251, in inner
    self._setup()
    ~~~~~~~~~~~^^
  File "C:\Users\PC\Desktop\intenship\protfolio\venv\Lib\site-packages\django\utils\functional.py", line 404, in _setup
    self._wrapped = self._setupfunc()
                    ~~~~~~~~~~~~~~~^^
  File "C:\Users\PC\Desktop\intenship\protfolio\venv\Lib\site-packages\django\contrib\auth\middleware.py", line 40, in <lambda>
    request.user = SimpleLazyObject(lambda: get_user(request))
                                            ~~~~~~~~^^^^^^^^^
  File "C:\Users\PC\Desktop\intenship\protfolio\venv\Lib\site-packages\django\contrib\auth\middleware.py", line 20, in get_user
    request._cached_user = auth.get_user(request)
                           ~~~~~~~~~~~~~^^^^^^^^^
  File "C:\Users\PC\Desktop\intenship\protfolio\venv\Lib\site-packages\django\contrib\auth\__init__.py", line 304, in get_user
    user_id = _get_user_session_key(request)
  File "C:\Users\PC\Desktop\intenship\protfolio\venv\Lib\site-packages\django\contrib\auth\__init__.py", line 95, in _get_user_session_key
    return get_user_model()._meta.pk.to_python(request.session[SESSION_KEY])
                                               ~~~~~~~~~~~~~~~^^^^^^^^^^^^^
  File "C:\Users\PC\Desktop\intenship\protfolio\venv\Lib\site-packages\django\contrib\sessions\backends\base.py", line 55, in __getitem__
    return self._session[key]
           ^^^^^^^^^^^^^
  File "C:\Users\PC\Desktop\intenship\protfolio\venv\Lib\site-packages\django\contrib\sessions\backends\base.py", line 249, in _get_session
    self._session_cache = self.load()
                          ~~~~~~~~~^^
  File "C:\Users\PC\Desktop\intenship\protfolio\venv\Lib\site-packages\django\contrib\sessions\backends\cached_db.py", line 46, in load
    self._cache.set(
    ~~~~~~~~~~~~~~~^
        self.cache_key, data, self.get_expiry_age(expiry=s.expire_date)
        ^^^^^^^^^^^^^^^^^^^^^^^^^^^^^^^^^^^^^^^^^^^^^^^^^^^^^^^^^^^^^^^
    )
    ^
  File "C:\Users\PC\Desktop\intenship\protfolio\venv\Lib\site-packages\django\core\cache\backends\db.py", line 103, in set
    self._base_set("set", key, value, timeout)
    ~~~~~~~~~~~~~~^^^^^^^^^^^^^^^^^^^^^^^^^^^^
  File "C:\Users\PC\Desktop\intenship\protfolio\venv\Lib\site-packages\django\core\cache\backends\db.py", line 121, in _base_set
    cursor.execute("SELECT COUNT(*) FROM %s" % table)
    ~~~~~~~~~~~~~~^^^^^^^^^^^^^^^^^^^^^^^^^^^^^^^^^^^
  File "C:\Users\PC\Desktop\intenship\protfolio\venv\Lib\site-packages\django\db\backends\utils.py", line 122, in execute
    return super().execute(sql, params)
           ~~~~~~~~~~~~~~~^^^^^^^^^^^^^
  File "C:\Users\PC\Desktop\intenship\protfolio\venv\Lib\site-packages\django\db\backends\utils.py", line 79, in execute
    return self._execute_with_wrappers(
           ~~~~~~~~~~~~~~~~~~~~~~~~~~~^
        sql, params, many=False, executor=self._execute
        ^^^^^^^^^^^^^^^^^^^^^^^^^^^^^^^^^^^^^^^^^^^^^^^
    )
    ^
  File "C:\Users\PC\Desktop\intenship\protfolio\venv\Lib\site-packages\django\db\backends\utils.py", line 92, in _execute_with_wrappers
    return executor(sql, params, many, context)
  File "C:\Users\PC\Desktop\intenship\protfolio\venv\Lib\site-packages\django\db\backends\utils.py", line 100, in _execute
    with self.db.wrap_database_errors:
         ^^^^^^^^^^^^^^^^^^^^^^^^^^^^
  File "C:\Users\PC\Desktop\intenship\protfolio\venv\Lib\site-packages\django\db\utils.py", line 91, in __exit__
    raise dj_exc_value.with_traceback(traceback) from exc_value
  File "C:\Users\PC\Desktop\intenship\protfolio\venv\Lib\site-packages\django\db\backends\utils.py", line 103, in _execute
    return self.cursor.execute(sql)
           ~~~~~~~~~~~~~~~~~~~^^^^^
  File "C:\Users\PC\Desktop\intenship\protfolio\venv\Lib\site-packages\django\db\backends\sqlite3\base.py", line 356, in execute
    return super().execute(query)
           ~~~~~~~~~~~~~~~^^^^^^^
django.db.utils.OperationalError: no such table: myapp_cache_table
ERROR 2025-10-24 15:22:43,826 basehttp 25460 22896 "GET / HTTP/1.1" 500 158988
ERROR 2025-10-24 15:37:38,414 views 28656 2460 Auto-reply email failed: (421, b'Cannot connect to SMTP server 172.217.215.109 (172.217.215.109:587), connect error 10060')
ERROR 2025-10-24 15:37:44,780 views 28656 20044 Auto-reply email failed: (421, b'Cannot connect to SMTP server 172.217.215.109 (172.217.215.109:587), connect error 10060')
ERROR 2025-10-24 15:40:35,790 views 28656 2460 Auto-reply email failed: (421, b'Cannot connect to SMTP server 64.233.166.109 (64.233.166.109:587), connect error 10060')
ERROR 2025-10-24 18:57:06,885 log 18964 26244 Invalid HTTP_HOST header: 'testserver'. You may need to add 'testserver' to ALLOWED_HOSTS.
Traceback (most recent call last):
  File "C:\Users\PC\Desktop\intenship\protfolio\venv\Lib\site-packages\django\core\handlers\exception.py", line 55, in inner
    response = get_response(request)
  File "C:\Users\PC\Desktop\intenship\protfolio\venv\Lib\site-packages\django\utils\deprecation.py", line 119, in __call__
    response = self.process_request(request)
  File "C:\Users\PC\Desktop\intenship\protfolio\venv\Lib\site-packages\django\middleware\security.py", line 28, in process_request
    host = self.redirect_host or request.get_host()
                                 ~~~~~~~~~~~~~~~~^^
  File "C:\Users\PC\Desktop\intenship\protfolio\venv\Lib\site-packages\django\http\request.py", line 202, in get_host
    raise DisallowedHost(msg)
django.core.exceptions.DisallowedHost: Invalid HTTP_HOST header: 'testserver'. You may need to add 'testserver' to ALLOWED_HOSTS.
ERROR 2025-10-24 18:57:06,979 log 18964 26244 Invalid HTTP_HOST header: 'testserver'. You may need to add 'testserver' to ALLOWED_HOSTS.
Traceback (most recent call last):
  File "C:\Users\PC\Desktop\intenship\protfolio\venv\Lib\site-packages\django\core\handlers\exception.py", line 55, in inner
    response = get_response(request)
  File "C:\Users\PC\Desktop\intenship\protfolio\venv\Lib\site-packages\django\utils\deprecation.py", line 119, in __call__
    response = self.process_request(request)
  File "C:\Users\PC\Desktop\intenship\protfolio\venv\Lib\site-packages\django\middleware\security.py", line 28, in process_request
    host = self.redirect_host or request.get_host()
                                 ~~~~~~~~~~~~~~~~^^
  File "C:\Users\PC\Desktop\intenship\protfolio\venv\Lib\site-packages\django\http\request.py", line 202, in get_host
    raise DisallowedHost(msg)
django.core.exceptions.DisallowedHost: Invalid HTTP_HOST header: 'testserver'. You may need to add 'testserver' to ALLOWED_HOSTS.
ERROR 2025-10-24 18:57:06,983 log 18964 26244 Invalid HTTP_HOST header: 'testserver'. You may need to add 'testserver' to ALLOWED_HOSTS.
Traceback (most recent call last):
  File "C:\Users\PC\Desktop\intenship\protfolio\venv\Lib\site-packages\django\core\handlers\exception.py", line 55, in inner
    response = get_response(request)
  File "C:\Users\PC\Desktop\intenship\protfolio\venv\Lib\site-packages\django\utils\deprecation.py", line 119, in __call__
    response = self.process_request(request)
  File "C:\Users\PC\Desktop\intenship\protfolio\venv\Lib\site-packages\django\middleware\security.py", line 28, in process_request
    host = self.redirect_host or request.get_host()
                                 ~~~~~~~~~~~~~~~~^^
  File "C:\Users\PC\Desktop\intenship\protfolio\venv\Lib\site-packages\django\http\request.py", line 202, in get_host
    raise DisallowedHost(msg)
django.core.exceptions.DisallowedHost: Invalid HTTP_HOST header: 'testserver'. You may need to add 'testserver' to ALLOWED_HOSTS.
ERROR 2025-10-24 18:57:06,987 log 18964 26244 Invalid HTTP_HOST header: 'testserver'. You may need to add 'testserver' to ALLOWED_HOSTS.
Traceback (most recent call last):
  File "C:\Users\PC\Desktop\intenship\protfolio\venv\Lib\site-packages\django\core\handlers\exception.py", line 55, in inner
    response = get_response(request)
  File "C:\Users\PC\Desktop\intenship\protfolio\venv\Lib\site-packages\django\utils\deprecation.py", line 119, in __call__
    response = self.process_request(request)
  File "C:\Users\PC\Desktop\intenship\protfolio\venv\Lib\site-packages\django\middleware\security.py", line 28, in process_request
    host = self.redirect_host or request.get_host()
                                 ~~~~~~~~~~~~~~~~^^
  File "C:\Users\PC\Desktop\intenship\protfolio\venv\Lib\site-packages\django\http\request.py", line 202, in get_host
    raise DisallowedHost(msg)
django.core.exceptions.DisallowedHost: Invalid HTTP_HOST header: 'testserver'. You may need to add 'testserver' to ALLOWED_HOSTS.
ERROR 2025-10-24 18:57:06,991 log 18964 26244 Invalid HTTP_HOST header: 'testserver'. You may need to add 'testserver' to ALLOWED_HOSTS.
Traceback (most recent call last):
  File "C:\Users\PC\Desktop\intenship\protfolio\venv\Lib\site-packages\django\core\handlers\exception.py", line 55, in inner
    response = get_response(request)
  File "C:\Users\PC\Desktop\intenship\protfolio\venv\Lib\site-packages\django\utils\deprecation.py", line 119, in __call__
    response = self.process_request(request)
  File "C:\Users\PC\Desktop\intenship\protfolio\venv\Lib\site-packages\django\middleware\security.py", line 28, in process_request
    host = self.redirect_host or request.get_host()
                                 ~~~~~~~~~~~~~~~~^^
  File "C:\Users\PC\Desktop\intenship\protfolio\venv\Lib\site-packages\django\http\request.py", line 202, in get_host
    raise DisallowedHost(msg)
django.core.exceptions.DisallowedHost: Invalid HTTP_HOST header: 'testserver'. You may need to add 'testserver' to ALLOWED_HOSTS.
ERROR 2025-10-24 18:57:06,995 log 18964 26244 Invalid HTTP_HOST header: 'testserver'. You may need to add 'testserver' to ALLOWED_HOSTS.
Traceback (most recent call last):
  File "C:\Users\PC\Desktop\intenship\protfolio\venv\Lib\site-packages\django\core\handlers\exception.py", line 55, in inner
    response = get_response(request)
  File "C:\Users\PC\Desktop\intenship\protfolio\venv\Lib\site-packages\django\utils\deprecation.py", line 119, in __call__
    response = self.process_request(request)
  File "C:\Users\PC\Desktop\intenship\protfolio\venv\Lib\site-packages\django\middleware\security.py", line 28, in process_request
    host = self.redirect_host or request.get_host()
                                 ~~~~~~~~~~~~~~~~^^
  File "C:\Users\PC\Desktop\intenship\protfolio\venv\Lib\site-packages\django\http\request.py", line 202, in get_host
    raise DisallowedHost(msg)
django.core.exceptions.DisallowedHost: Invalid HTTP_HOST header: 'testserver'. You may need to add 'testserver' to ALLOWED_HOSTS.
ERROR 2025-10-24 18:57:07,035 log 18964 26244 Invalid HTTP_HOST header: 'testserver'. You may need to add 'testserver' to ALLOWED_HOSTS.
Traceback (most recent call last):
  File "C:\Users\PC\Desktop\intenship\protfolio\venv\Lib\site-packages\django\core\handlers\exception.py", line 55, in inner
    response = get_response(request)
  File "C:\Users\PC\Desktop\intenship\protfolio\venv\Lib\site-packages\django\utils\deprecation.py", line 119, in __call__
    response = self.process_request(request)
  File "C:\Users\PC\Desktop\intenship\protfolio\venv\Lib\site-packages\django\middleware\security.py", line 28, in process_request
    host = self.redirect_host or request.get_host()
                                 ~~~~~~~~~~~~~~~~^^
  File "C:\Users\PC\Desktop\intenship\protfolio\venv\Lib\site-packages\django\http\request.py", line 202, in get_host
    raise DisallowedHost(msg)
django.core.exceptions.DisallowedHost: Invalid HTTP_HOST header: 'testserver'. You may need to add 'testserver' to ALLOWED_HOSTS.
ERROR 2025-10-25 08:30:51,449 views 25412 26540 Auto-reply email failed: [SSL: CERTIFICATE_VERIFY_FAILED] certificate verify failed: Basic Constraints of CA cert not marked critical (_ssl.c:1028)
ERROR 2025-10-25 08:30:51,449 views 25412 24620 Auto-reply email failed: [SSL: CERTIFICATE_VERIFY_FAILED] certificate verify failed: Basic Constraints of CA cert not marked critical (_ssl.c:1028)
ERROR 2025-10-25 08:56:42,730 views 25412 24620 Auto-reply email failed: [SSL: CERTIFICATE_VERIFY_FAILED] certificate verify failed: Basic Constraints of CA cert not marked critical (_ssl.c:1028)
ERROR 2025-10-25 09:16:43,881 basehttp 21964 16764 You're accessing the development server over HTTPS, but it only supports HTTP.
ERROR 2025-10-25 09:16:43,890 basehttp 21964 1380 You're accessing the development server over HTTPS, but it only supports HTTP.
ERROR 2025-10-25 09:16:43,896 basehttp 21964 13180 You're accessing the development server over HTTPS, but it only supports HTTP.
ERROR 2025-10-25 09:16:43,897 basehttp 21964 1544 You're accessing the development server over HTTPS, but it only supports HTTP.
ERROR 2025-10-25 09:17:03,825 basehttp 21964 12104 You're accessing the development server over HTTPS, but it only supports HTTP.
ERROR 2025-10-25 09:17:03,829 basehttp 21964 21320 You're accessing the development server over HTTPS, but it only supports HTTP.
